Workbook

Sheet Top 100 (not on Spotify)
A1: 100 big LATAM YouTube channels NOT on Spotify: Gaming, Comedy, Family, Lifestyle (25 each)
A2: YouTube stats and country from each channel's About page; Spotify checked 27 Sep 2026 (Spotify search for shows/podcasts and artists, plus Spotify links on the channel's YouTube page). Yellow = replacement for a channel found on Spotify.
A3: # | B3: Channel | C3: Category | D3: Country | E3: Language | F3: Subscribers | G3: Total views | H3: Videos | I3: Joined YouTube | J3: Channel URL | K3: Handle | L3: Spotify status | M3: Spotify evidence | N3: Replacement? | O3: Notes
A4: 1 | B4: TheDonato | C4: Gaming | D4: Argentina | E4: Spanish | F4: 43700000 | G4: 8617717644 | H4: 4151 | I4: Feb 16, 2015 | J4: https://www.youtube.com/@thedonato | K4: @thedonato | L4: Not on Spotify | M4: No matching show or artist found; no Spotify link on YouTube page | N4: No
A5: 2 | B5: Jazzghost | C5: Gaming | D5: Brazil | E5: Portuguese | F5: 24800000 | G5: 11621584884 | H5: 6473 | I5: Aug 30, 2012 | J5: https://www.youtube.com/@Jazzghost | K5: @Jazzghost | L5: Not on Spotify | M5: No matching show or artist found; no Spotify link on YouTube page | N5: No | O5: Country not set on YouTube; creator origin per public info
A6: 3 | B6: Robin Hood Gamer | C6: Gaming | D6: Brazil | E6: Portuguese | F6: 22600000 | G6: 12159411872 | H6: 4644 | I6: May 17, 2014 | J6: https://www.youtube.com/@RobinHoodGamer1 | K6: @RobinHoodGamer1 | L6: Not on Spotify | M6: No matching show or artist found; no Spotify link on YouTube page | N6: No
A7: 4 | B7: AuthenticGames | C7: Gaming | D7: Brazil | E7: Portuguese | F7: 20200000 | G7: 9022545695 | H7: 4842 | I7: Oct 6, 2011 | J7: https://www.youtube.com/@AuthenticGames | K7: @AuthenticGames | L7: Not on Spotify | M7: No matching show or artist found; no Spotify link on YouTube page | N7: No
A8: 5 | B8: T3ddy | C8: Gaming | D8: Brazil | E8: Portuguese | F8: 19300000 | G8: 4104448821 | H8: 2828 | I8: Jan 15, 2012 | J8: https://www.youtube.com/@T3ddy | K8: @T3ddy | L8: Not on Spotify | M8: Only fan uploads / same-name artists found (not the creator) | N8: No
A9: 6 | B9: TazerCraft | C9: Gaming | D9: Brazil | E9: Portuguese | F9: 15100000 | G9: 6275055396 | H9: 4179 | I9: Jul 12, 2011 | J9: https://www.youtube.com/@TazerCraft | K9: @TazerCraft | L9: Not on Spotify | M9: No matching show or artist found; no Spotify link on YouTube page | N9: No
A10: 7 | B10: ElAbrahaham | C10: Gaming | D10: Mexico | E10: Spanish | F10: 13900000 | G10: 3770613392 | H10: 2376 | I10: Feb 6, 2019 | J10: https://www.youtube.com/@ElAbrahaham | K10: @ElAbrahaham | L10: Not on Spotify | M10: No matching show or artist found; no Spotify link on YouTube page | N10: Yes
A11: 8 | B11: Piuzinho | C11: Gaming | D11: Brazil | E11: Portuguese | F11: 12800000 | G11: 1156708267 | H11: 672 | I11: May 13, 2015 | J11: https://www.youtube.com/@piuzinho | K11: @piuzinho | L11: Not on Spotify | M11: No matching show or artist found; no Spotify link on YouTube page | N11: No
A12: 9 | B12: ProbIems | C12: Gaming | D12: Brazil | E12: Portuguese | F12: 12500000 | G12: 10090222992 | H12: 5493 | I12: Aug 30, 2021 | J12: https://www.youtube.com/@problemsyt | K12: @problemsyt | L12: Not on Spotify | M12: No matching show or artist found; no Spotify link on YouTube page | N12: Yes
A13: 10 | B13: Golemcito Games | C13: Gaming | D13: Peru | E13: Spanish | F13: 12100000 | G13: 1371882615 | H13: 854 | I13: Apr 25, 2015 | J13: https://www.youtube.com/@GolemcitoGames | K13: @GolemcitoGames | L13: Not on Spotify | M13: No matching show or artist found; no Spotify link on YouTube page | N13: Yes
A14: 11 | B14: Silvio Gamer | C14: Gaming | D14: Mexico | E14: Spanish | F14: 11400000 | G14: 4922581889 | H14: 1371 | I14: May 2, 2016 | J14: https://www.youtube.com/@SilvioGamer | K14: @SilvioGamer | L14: Not on Spotify | M14: No matching show or artist found; no Spotify link on YouTube page | N14: Yes
A15: 12 | B15: Geleia | C15: Gaming | D15: Brazil | E15: Portuguese | F15: 10800000 | G15: 3529255307 | H15: 2451 | I15: Jul 22, 2016 | J15: https://www.youtube.com/@geleia0 | K15: @geleia0 | L15: Not on Spotify | M15: Only fan uploads / same-name artists found (not the creator) | N15: No
A16: 13 | B16: ElMariana Gaming | C16: Gaming | D16: Mexico | E16: Spanish | F16: 9790000 | G16: 2385854364 | H16: 1024 | I16: Jan 12, 2017 | J16: https://www.youtube.com/@ElMarianaJuega | K16: @ElMarianaJuega | L16: Not on Spotify | M16: No matching show or artist found; no Spotify link on YouTube page | N16: No
A17: 14 | B17: alanzoka | C17: Gaming | D17: Brazil | E17: Portuguese | F17: 9290000 | G17: 2671658000 | H17: 4618 | I17: Apr 26, 2011 | J17: https://www.youtube.com/@alanzoka | K17: @alanzoka | L17: Not on Spotify | M17: No matching show or artist found; no Spotify link on YouTube page | N17: No
... A31: 28 | B31: Rubén Tuesta oficial | C31: Comedy | D31: Mexico | E31: Spanish | F31: 29400000 | G31: 22743844638 | H31: 1906 | I31: Aug 2, 2016 | J31: https://www.youtube.com/@Tuestaok | K31: @Tuestaok | L31: Not on Spotify | M31: No matching show or artist found; no Spotify link on YouTube page | N31: No
A32: 29 | B32: enchufetv | C32: Comedy | D32: Ecuador | E32: Spanish | F32: 29300000 | G32: 11887011168 | H32: 2850 | I32: Nov 12, 2011 | J32: https://www.youtube.com/@enchufetv | K32: @enchufetv | L32: Not on Spotify | M32: No matching show or artist found; no Spotify link on YouTube page | N32: No | O32: Country not set on YouTube; creator origin per public info
A33: 30 | B33: DrossRotzank | C33: Comedy | D33: Argentina | E33: Spanish | F33: 24200000 | G33: 7275007340 | H33: 2103 | I33: Mar 9, 2006 | J33: https://www.youtube.com/@DrossRotzank | K33: @DrossRotzank | L33: Not on Spotify | M33: Only fan uploads / same-name artists found (not the creator) | N33: No
A34: 31 | B34: O Que Não Dizer Oficial | C34: Comedy | D34: Brazil | E34: Portuguese | F34: 17300000 | G34: 4824098773 | H34: 1371 | I34: Feb 6, 2015 | J34: https://www.youtube.com/@WillouMaisWatson | K34: @WillouMaisWatson | L34: Not on Spotify | M34: No matching show or artist found; no Spotify link on YouTube page | N34: No
A35: 32 | B35: Werever2morro | C35: Comedy | D35: Mexico | E35: Spanish | F35: 16500000 | G35: 2863157173 | H35: 986 | I35: Feb 27, 2007 | J35: https://www.youtube.com/@werevertumorro | K35: @werevertumorro | L35: Not on Spotify | M35: No matching show or artist found; no Spotify link on YouTube page | N35: No | O35: Country not set on YouTube; creator origin per public info
A36: 33 | B36: Invento na Hora | C36: Comedy | D36: Brazil | E36: Portuguese | F36: 14100000 | G36: 4255579375 | H36: 1433 | I36: Oct 18, 2014 | J36: https://www.youtube.com/@inventonahora | K36: @inventonahora | L36: Not on Spotify | M36: Only fan uploads / same-name artists found (not the creator) | N36: No
A37: 34 | B37: Everson Zoio | C37: Comedy | D37: Brazil | E37: Portuguese | F37: 13300000 | G37: 1028511222 | H37: 612 | I37: Mar 26, 2009 | J37: https://www.youtube.com/@EversonZoioo | K37: @EversonZoioo | L37: Not on Spotify | M37: Only fan uploads / same-name artists found (not the creator) | N37: No
A38: 35 | B38: Vetor Humor | C38: Comedy | D38: Brazil | E38: Portuguese | F38: 12600000 | G38: 4890181933 | H38: 2546 | I38: May 13, 2011 | J38: https://www.youtube.com/@vetorhumor | K38: @vetorhumor | L38: Not on Spotify | M38: No matching show or artist found; no Spotify link on YouTube page | N38: No
A39: 36 | B39: 5incominutos | C39: Comedy | D39: Brazil | E39: Portuguese | F39: 10400000 | G39: 783434340 | H39: 288 | I39: Jul 25, 2010 | J39: https://www.youtube.com/@5incominutos | K39: @5incominutos | L39: Not on Spotify | M39: No matching show or artist found; no Spotify link on YouTube page | N39: No
A40: 37 | B40: COMÉDIA SELVAGEM | C40: Comedy | D40: Brazil | E40: Portuguese | F40: 10200000 | G40: 3807618133 | H40: 1804 | I40: May 3, 2017 | J40: https://www.youtube.com/@comediaselvagem_oficial | K40: @comediaselvagem_oficial | L40: Not on Spotify | M40: No matching show or artist found; no Spotify link on YouTube page | N40: No
A41: 38 | B41: Bruno Correa | C41: Comedy | D41: Brazil | E41: Portuguese | F41: 7650000 | G41: 1025366525 | H41: 2689 | I41: Sep 10, 2011 | J41: https://www.youtube.com/@brunocorrea | K41: @brunocorrea | L41: Not on Spotify | M41: Only fan uploads / same-name artists found (not the creator) | N41: Yes
A42: 39 | B42: Isaac do VINE | C42: Comedy | D42: Brazil | E42: Portuguese | F42: 7450000 | G42: 876772221 | H42: 561 | I42: Oct 24, 2014 | J42: https://www.youtube.com/@IsaacdoVINE | K42: @IsaacdoVINE | L42: Not on Spotify | M42: No matching show or artist found; no Spotify link on YouTube page | N42: Yes
A43: 40 | B43: Distrito Comedia | C43: Comedy | D43: Mexico | E43: Spanish | F43: 7330000 | G43: 9438121152 | H43: 12146 | I43: Apr 8, 2013 | J43: https://www.youtube.com/@DistritoComediaOf | K43: @DistritoComediaOf | L43: Not on Spotify | M43: No matching show or artist found; no Spotify link on YouTube page | N43: Yes
A44: 41 | B44: Prankedy | C44: Comedy | D44: Mexico | E44: Spanish | F44: 6860000 | G44: 1377591159 | H44: 342 | I44: Oct 12, 2013 | J44: https://www.youtube.com/@Prankedy | K44: @Prankedy | L44: Not on Spotify | M44: No matching show or artist found; no Spotify link on YouTube page | N44: Yes
A45: 42 | B45: Rafael Chocolate | C45: Comedy | D45: Brazil | E45: Portuguese | F45: 5400000 | G45: 777843055 | H45: 357 | I45: Nov 9, 2016 | J45: https://www.youtube.com/@rafaelchocolate | K45: @rafaelchocolate | L45: Not on Spotify | M45: No matching show or artist found; no Spotify link on YouTube page | N45: Yes
A46: 43 | B46: Tirú TV | C46: Comedy | D46: Brazil | E46: Portuguese | F46: 5280000 | G46: 666068226 | H46: 2195 | I46: Mar 11, 2013 | J46: https://www.youtube.com/@TiruTV | K46: @TiruTV | L46: Not on Spotify | M46: No matching show or artist found; no Spotify link on YouTube page | N46: Yes
A47: 44 | B47: Chilin y Pikin oficial | C47: Comedy | D47: Mexico | E47: Spanish | F47: 5130000 | G47: 4231254711 | H47: 751 | I47: Sep 2, 2015 | J47: https://www.youtube.com/@chilinypikinoficial | K47: @chilinypikinoficial | L47: Not on Spotify | M47: No matching show or artist found; no Spotify link on YouTube page | N47: Yes
... A103: 100 | B103: Fabio Fregona - BACA | C103: Lifestyle | D103: Brazil | E103: Portuguese | F103: 2500000 | G103: 728986698 | H103: 641 | I103: Dec 16, 2009 | J103: https://www.youtube.com/@fabio_baca | K103: @fabio_baca | L103: Not on Spotify | M103: No matching show or artist found; no Spotify link on YouTube page | N103: Yes

Sheet Removed - on Spotify
A1: 51 channels removed from the original list because they are on Spotify
A2: Evidence column links the Spotify show/artist found, or the Spotify link on the channel's own YouTube page.
A3: # | B3: Channel | C3: Category | D3: Country | E3: Language | F3: Subscribers | G3: Total views | H3: Videos | I3: Joined YouTube | J3: Channel URL | K3: Handle | L3: Spotify status | M3: Spotify evidence | N3: Notes
A4: 1 | B4: JuegaGerman | C4: Gaming | D4: Chile | E4: Spanish | F4: 56700000 | G4: 19095580013 | H4: 2510 | I4: May 18, 2013 | J4: https://www.youtube.com/@JuegaGerman | K4: @JuegaGerman | L4: On Spotify | M4: YouTube channel links to Spotify: open.spotify.com/track/3knMu0WxnpUravTlT7HrKY?si=KHP-eLHbSDOZrxnx9zb8Cw
A5: 2 | B5: Fernanfloo | C5: Gaming | D5: El Salvador | E5: Spanish | F5: 50700000 | G5: 11167145992 | H5: 606 | I5: May 1, 2011 | J5: https://www.youtube.com/@Fernanfloo | K5: @Fernanfloo | L5: On Spotify | M5: Spotify artist "Fernanfloo": https://open.spotify.com/artist/2pKoDkP2EqXNjDquMQjbM8
A6: 3 | B6: rezendeevil | C6: Gaming | D6: Brazil | E6: Portuguese | F6: 34600000 | G6: 14392261484 | H6: 13377 | I6: Feb 12, 2012 | J6: https://www.youtube.com/@rezendeevil | K6: @rezendeevil | L6: On Spotify | M6: Spotify artist "rezendeevil": https://open.spotify.com/artist/0DUtREON3ylMPprePq2wPm
A7: 4 | B7: DeGoBooM | C7: Gaming | D7: Chile | E7: Spanish | F7: 24200000 | G7: 7959487025 | H7: 5920 | I7: Jan 31, 2014 | J7: https://www.youtube.com/@degoboom | K7: @degoboom | L7: On Spotify | M7: YouTube channel links to Spotify: spoti.fi/392bkXq
A8: 5 | B8: Gato Galactico | C8: Gaming | D8: Brazil | E8: Portuguese | F8: 20600000 | G8: 4200688998 | H8: 1761 | I8: Apr 2, 2013 | J8: https://www.youtube.com/@GatoGalactico | K8: @GatoGalactico | L8: On Spotify | M8: Spotify artist "Gato Galactico": https://open.spotify.com/artist/4V6Zqhu9BQ5drXHBUB7q5z
A9: 6 | B9: RobleisIUTU | C9: Gaming | D9: Argentina | E9: Spanish | F9: 20500000 | G9: 7269742253 | H9: 2478 | I9: Apr 15, 2013 | J9: https://www.youtube.com/@RobleisIUTU | K9: @RobleisIUTU | L9: On Spotify | M9: YouTube channel links to Spotify: open.spotify.com/artist/32AuV4BxATEf2i7YVhIjht?si=TD3bjrWKSUS13AUDEFLOJQ
A10: 7 | B10: NOBRU | C10: Gaming | D10: Brazil | E10: Portuguese | F10: 16500000 | G10: 713348087 | H10: 1350 | I10: Feb 23, 2016 | J10: https://www.youtube.com/@NobruTV | K10: @NobruTV | L10: On Spotify | M10: Spotify show "nobru" (Pedro Santana): https://open.spotify.com/show/28xcmuLTlj6wshH74lnx7F
A11: 8 | B11: Spreen | C11: Gaming | D11: Argentina | E11: Spanish | F11: 8460000 | G11: 2181488558 | H11: 692 | I11: Jan 24, 2016 | J11: https://www.youtube.com/@Spreen | K11: @Spreen | L11: On Spotify | M11: Spotify artist "Spreen": https://open.spotify.com/artist/1NIDfe1B5J1EyNiJcPZsfZ
A12: 9 | B12: LOUD Coringa | C12: Gaming | D12: Brazil | E12: Portuguese | F12: 7890000 | G12: 926282583 | H12: 1736 | I12: Jan 29, 2019 | J12: https://www.youtube.com/@LOUDCoringa | K12: @LOUDCoringa | L12: On Spotify | M12: Spotify artist "Loud Coringa": https://open.spotify.com/artist/1Xuc6It0QclXYnwtbP7QYx | N12: Country not set on YouTube; creator origin per public info
A13: 10 | B13: Fede Vigevani | C13: Comedy | D13: Mexico | E13: Spanish | F13: 79000000 | G13: 29287347888 | H13: 1744 | I13: Jun 16, 2009 | J13: https://www.youtube.com/@fedevigevani | K13: @fedevigevani | L13: On Spotify | M13: Spotify show "Fede Vigevani" (): https://open.spotify.com/show/033YIZ6oAspfRBW5K5Pm5X
A14: 11 | B14: YOLO AVENTURAS | C14: Comedy | D14: Mexico | E14: Spanish | F14: 70900000 | G14: 29741698513 | H14: 3619 | I14: Dec 13, 2018 | J14: https://www.youtube.com/@YOLOAVENTURAS | K14: @YOLOAVENTURAS | L14: On Spotify | M14: YouTube channel links to Spotify: open.spotify.com%2Ftrack%2F2g3XrO2h0kAUc474YWkhSL
A15: 12 | B15: Badabun | C15: Comedy | D15: Mexico | E15: Spanish | F15: 47600000 | G15: 20371842295 | H15: 30301 | I15: Oct 13, 2014 | J15: https://www.youtube.com/@badabunOficial | K15: @badabunOficial | L15: On Spotify | M15: Spotify show "Badabun" (Network ®): https://open.spotify.com/show/0PJ87iXtEauyF0irceUjbY
A16: 13 | B16: HolaSoyGerman. | C16: Comedy | D16: Chile | E16: Spanish | F16: 44600000 | G16: 4994058504 | H16: 136 | I16: Sep 8, 2011 | J16: https://www.youtube.com/@HolaSoyGerman | K16: @HolaSoyGerman | L16: On Spotify | M16: Spotify show "HolaSoyGerman" (Augustinolo): https://open.spotify.com/show/4IPdoQ0f0BSMzBD3uRPAUm
A17: 14 | B17: whinderssonnunes | C17: Comedy | D17: Brazil | E17: Portuguese | F17: 44600000 | G17: 4773038313 | H17: 1487 | I17: Jan 21, 2013 | J17: https://www.youtube.com/@whindersson | K17: @whindersson | L17: On Spotify | M17: Spotify artist "Whindersson Nunes": https://open.spotify.com/artist/2emd6h8cx0U8QUAxDddXPF
A18: 15 | B18: LosPolinesios | C18: Comedy | D18: Mexico | E18: Spanish | F18: 27400000 | G18: 9067468763 | H18: 1514 | I18: Dec 16, 2012 | J18: https://www.youtube.com/@LosPolinesios | K18: @LosPolinesios | L18: On Spotify | M18: Spotify show "LOS_POLINESIOS" (David Corral Larrinaga): https://open.spotify.com/show/6UilyNQtXWKqjooJHHdPeO | N18: Country not set on YouTube; creator origin per public info
A19: 16 | B19: Porta dos Fundos | C19: Comedy | D19: Brazil | E19: Portuguese | F19: 19200000 | G19: 9500566843 | H19: 3790 | I19: Mar 11, 2012 | J19: https://www.youtube.com/@portadosfundos | K19: @portadosfundos | L19: On Spotify | M19: Spotify artist "Porta dos Fundos": https://open.spotify.com/artist/0p0LTPqXYVrIXsZeeq0xZ5
A20: 17 | B20: Franco Escamilla | C20: Comedy | D20: Mexico | E20: Spanish | F20: 14400000 | G20: 6383753021 | H20: 4619 | I20: Oct 19, 2007 | J20: https://www.youtube.com/@francoescamilla | K20: @francoescamilla | L20: On Spotify | M20: Spotify show "Franco Escamilla Canal Oficial" (Franco Escamilla): https://open.spotify.com/show/61ALehw2tPTvPtycY6hFWl
A21: 18 | B21: Lucas Rangel | C21: Comedy | D21: Brazil | E21: Portuguese | F21: 13200000 | G21: 3668119973 | H21: 1122 | I21: Feb 11, 2014 | J21: https://www.youtube.com/@lucasranngel | K21: @lucasranngel | L21: On Spotify | M21: Spotify show "Lucas Rangel" (ana carolina baiense): https://open.spotify.com/show/0gzCmKJXPcpQ3SF7FHLCr5
A22: 19 | B22: Juanpa Zurita | C22: Comedy | D22: Mexico | E22: Spanish | F22: 11300000 | G22: 978639051 | H22: 414 | I22: Oct 5, 2013 | J22: https://www.youtube.com/@juanpazurita | K22: @juanpazurita | L22: On Spotify | M22: YouTube channel links to Spotify: open.spotify.com/show/19K7R0n3c9uwMfHldd3Px7?si=c24b235688ee41a0
A23: 20 | B23: Galo Frito | C23: Comedy | D23: Brazil | E23: Portuguese | F23: 10900000 | G23: 2010658730 | H23: 688 | I23: Oct 3, 2007 | J23: https://www.youtube.com/@galofrito | K23: @galofrito | L23: On Spotify | M23: Spotify show "Galo frito" (.): https://open.spotify.com/show/38hOzOxwmwHH1ngrBBjCWj
A24: 21 | B24: LA DIVAZA | C24: Comedy | D24: Mexico | E24: Spanish | F24: 10400000 | G24: 944241682 | H24: 237 | I24: Dec 9, 2012 | J24: https://www.youtube.com/@ladivaza | K24: @ladivaza | L24: On Spotify | M24: Spotify artist "La Divaza": https://open.spotify.com/artist/2BYegEOEQj3G3x6ltkFkZM
A25: 22 | B25: Podpah TV | C25: Comedy | D25: Brazil | E25: Portuguese | F25: 10200000 | G25: 2000582074 | H25: 5215 | I25: Sep 19, 2020 | J25: https://www.youtube.com/@Podpah | K25: @Podpah | L25: On Spotify | M25: Spotify show "Podpah" (): https://open.spotify.com/show/1GLSDdk9CDEwziGNIlnb8a
A26: 23 | B26: LUCCAS NETO | C26: Family | D26: Brazil | E26: Portuguese | F26: 53600000 | G26: 15611312607 | H26: 5135 | I26: Jul 30, 2014 | J26: https://www.youtube.com/@luccasneto | K26: @luccasneto | L26: On Spotify | M26: Spotify show "Luccas Neto" (Leticia leticia): https://open.spotify.com/show/0AVBTktL92Q9ssOgYCPQ6a
A27: 24 | B27: Enaldinho | C27: Family | D27: Brazil | E27: Portuguese | F27: 48300000 | G27: 26300097508 | H27: 5751 | I27: Nov 7, 2012 | J27: https://www.youtube.com/@enaldinho | K27: @enaldinho | L27: On Spotify | M27: Spotify artist "Enaldinho": https://open.spotify.com/artist/7dEZt5YKVPPUZ8S4mVvupa
A28: 25 | B28: Kimberly Loaiza | C28: Family | D28: Mexico | E28: Spanish | F28: 47600000 | G28: 7498339707 | H28: 314 | I28: Nov 15, 2016 | J28: https://www.youtube.com/@KimberlyLoaiza | K28: @KimberlyLoaiza | L28: On Spotify | M28: Spotify show "Kimberly Loaiza" (Angelito): https://open.spotify.com/show/6YJLYlW3o6IuMxnuvPrQm9
A29: 26 | B29: Ami Rodriguez | C29: Family | D29: Colombia | E29: Spanish | F29: 32299999 | G29: 6702525333 | H29: 939 | I29: Jul 20, 2009 | J29: https://www.youtube.com/@AmiRodrigueZZ | K29: @AmiRodrigueZZ | L29: On Spotify | M29: Spotify artist "Ami Rodriguezz": https://open.spotify.com/artist/4P5rq4W7tpIy0Y8THbuUjb
A30: 27 | B30: Juliana Baltar | C30: Family | D30: Brazil | E30: Portuguese | F30: 19900000 | G30: 5400082461 | H30: 3463 | I30: May 9, 2010 | J30: https://www.youtube.com/@JulianaBaltar | K30: @JulianaBaltar | L30: On Spotify | M30: Spotify artist "Juliana Baltar": https://open.spotify.com/artist/3oT8PyHL7h9V0tfbHWqRJU
... A44: 41 | B44: Luisito Comunica | C44: Lifestyle | D44: Mexico | E44: Spanish | F44: 46000000 | G44: 12002432702 | H44: 1473 | I44: Apr 14, 2012 | J44: https://www.youtube.com/@luisitocomunica | K44: @luisitocomunica | L44: On Spotify | M44: Spotify show "Luisito Comunica" (): https://open.spotify.com/show/4A6QP8KH3bXXWgStyC4pKE
A45: 42 | B45: Yuya | C45: Lifestyle | D45: Mexico | E45: Spanish | F45: 24500000 | G45: 2597452545 | H45: 672 | I45: Sep 20, 2009 | J45: https://www.youtube.com/@Yuya | K45: @Yuya | L45: On Spotify | M45: Spotify artist "yuya": https://open.spotify.com/artist/5a5aNFlfON5Coivexl51DV | N45: Country not set on YouTube; creator origin per public info
A46: 43 | B46: JukiLop | C46: Lifestyle | D46: Mexico | E46: Spanish | F46: 19800000 | G46: 1631014909 | H46: 85 | I46: Sep 15, 2017 | J46: https://www.youtube.com/@JukiLop | K46: @JukiLop | L46: On Spotify | M46: Spotify show "Jukilop🌷" (Dayana Trujillo): https://open.spotify.com/show/6rVhZJ0TBl1VMAo6MqEtNA
A47: 44 | B47: Camila Loures | C47: Lifestyle | D47: Brazil | E47: Portuguese | F47: 16300000 | G47: 6229001122 | H47: 5875 | I47: May 26, 2014 | J47: https://www.youtube.com/@camilaloures | K47: @camilaloures | L47: On Spotify | M47: Spotify show "Camila loures" (Alessandra Silva): https://open.spotify.com/show/3nYZmzeWZVlWoHl1qzGLws
A48: 45 | B48: Canal Nostalgia | C48: Lifestyle | D48: Brazil | E48: Portuguese | F48: 15200000 | G48: 1662001160 | H48: 467 | I48: Sep 20, 2008 | J48: https://www.youtube.com/@nostalgia | K48: @nostalgia | L48: On Spotify | M48: YouTube channel links to Spotify: open.spotify.com/show/7ejzHmb7Rx5cH3oUihfHLM
A49: 46 | B49: luisitorey | C49: Lifestyle | D49: Mexico | E49: Spanish | F49: 9570000 | G49: 2077473873 | H49: 1804 | I49: Mar 10, 2006 | J49: https://www.youtube.com/@luisitorey | K49: @luisitorey | L49: On Spotify | M49: Spotify artist "Luisito Rey": https://open.spotify.com/artist/1bdgHvfW3oLuPbeHEJeAqR
A50: 47 | B50: Calle y Poché | C50: Lifestyle | D50: Colombia | E50: Spanish | F50: 7270000 | G50: 691522039 | H50: 695 | I50: Oct 15, 2015 | J50: https://www.youtube.com/@CallePoche | K50: @CallePoche | L50: On Spotify | M50: YouTube channel links to Spotify: open.spotify.com/show/22sEY5ngb39KuHDm4BtU5n
A51: 48 | B51: Kenia Os | C51: Lifestyle | D51: Mexico | E51: Spanish | F51: 6580000 | G51: 2544402945 | H51: 502 | I51: Jul 29, 2018 | J51: https://www.youtube.com/@KeniaOs | K51: @KeniaOs | L51: On Spotify | M51: Spotify show "Kenia Os" (jazmin): https://open.spotify.com/show/5hAA1tt0MlRRef5H5c6GwV
A52: 49 | B52: Bianca Andrade | C52: Lifestyle | D52: Brazil | E52: Portuguese | F52: 5620000 | G52: 419841669 | H52: 659 | I52: Mar 8, 2011 | J52: https://www.youtube.com/@BiancaAndradeBR | K52: @BiancaAndradeBR | L52: On Spotify | M52: Spotify artist "Bianca Andrade": https://open.spotify.com/artist/7zOgXenMewWD1RzT6QsNww
A53: 50 | B53: Luisa Fernanda W | C53: Lifestyle | D53: Colombia | E53: Spanish | F53: 4460000 | G53: 237659354 | H53: 37 | I53: Mar 4, 2013 | J53: https://www.youtube.com/@LuisaFernandaW | K53: @LuisaFernandaW | L53: On Spotify | M53: Spotify artist "Luisa Fernanda W": https://open.spotify.com/artist/3iKdkIEoOGT55KE72tSOgU
...

Sheet Extra (not on Spotify)
A1: 26 more LATAM channels (2M+ subs) that are not on Spotify
A2: Backup options if you want to swap any channel in the Top 100.
A3: # | B3: Channel | C3: Category | D3: Country | E3: Language | F3: Subscribers | G3: Total views | H3: Videos | I3: Joined YouTube | J3: Channel URL | K3: Handle | L3: Spotify status | M3: Spotify evidence | N3: Notes
A4: 1 | B4: Rivers | C4: Gaming | D4: Mexico | E4: Spanish | F4: 4660000 | G4: 756335048 | H4: 686 | I4: Dec 1, 2020 | J4: https://www.youtube.com/@Rivers_gg | K4: @Rivers_gg | L4: Not on Spotify | M4: Only fan uploads / same-name artists found (not the creator)
A5: 2 | B5: LAS LEONCITAS KIDS | C5: Family | D5: Mexico | E5: Spanish | F5: 4170000 | G5: 1494067973 | H5: 87 | I5: Nov 6, 2012 | J5: https://www.youtube.com/@LASLEONCITASKIDS | K5: @LASLEONCITASKIDS | L5: Not on Spotify | M5: No matching show or artist found; no Spotify link on YouTube page
A6: 3 | B6: Isa y Nati | C6: Family | D6: Mexico | E6: Spanish | F6: 4110000 | G6: 3211526123 | H6: 2105 | I6: Jan 3, 2022 | J6: https://www.youtube.com/@Isaynati | K6: @Isaynati | L6: Not on Spotify | M6: No matching show or artist found; no Spotify link on YouTube page
A7: 4 | B7: Mirysita Blox💙 | C7: Gaming | D7: Mexico | E7: Spanish | F7: 3530000 | G7: 1880180310 | H7: 864 | I7: Sep 15, 2024 | J7: https://www.youtube.com/@Mirysita | K7: @Mirysita | L7: Not on Spotify | M7: No matching show or artist found; no Spotify link on YouTube page
A8: 5 | B8: BuX VLOGS | C8: Family | D8: Mexico | E8: Spanish | F8: 3490000 | G8: 5676999693 | H8: 1143 | I8: Mar 1, 2021 | J8: https://www.youtube.com/@buxvlogs | K8: @buxvlogs | L8: Not on Spotify | M8: No matching show or artist found; no Spotify link on YouTube page
A9: 6 | B9: familia ferro | C9: Family | D9: Argentina | E9: Spanish | F9: 3460000 | G9: 896526593 | H9: 1116 | I9: Jan 28, 2020 | J9: https://www.youtube.com/@FamiliaFerro | K9: @FamiliaFerro | L9: Not on Spotify | M9: No matching show or artist found; no Spotify link on YouTube page
A10: 7 | B10: WELIX | C10: Gaming | D10: Brazil | E10: Portuguese | F10: 3340000 | G10: 968519503 | H10: 2055 | I10: Apr 3, 2022 | J10: https://www.youtube.com/@Welix_OFICIAL | K10: @Welix_OFICIAL | L10: Not on Spotify | M10: No matching show or artist found; no Spotify link on YouTube page
A11: 8 | B11: Mamute Reagindo | C11: Gaming | D11: Brazil | E11: Portuguese | F11: 3270000 | G11: 298879577 | H11: 970 | I11: Mar 15, 2021 | J11: https://www.youtube.com/@MamuteReagindo | K11: @MamuteReagindo | L11: Not on Spotify | M11: No matching show or artist found; no Spotify link on YouTube page
A12: 9 | B12: Laos | C12: Gaming | D12: Panama | E12: Spanish | F12: 3030000 | G12: 2563396239 | H12: 723 | I12: Oct 15, 2023 | J12: https://www.youtube.com/@LaosOneVieww | K12: @LaosOneVieww | L12: Not on Spotify | M12: No matching show or artist found; no Spotify link on YouTube page
A13: 10 | B13: ElJuaniquilador | C13: Gaming | D13: Mexico | E13: Spanish | F13: 3020000 | G13: 375831718 | H13: 447 | I13: Feb 5, 2020 | J13: https://www.youtube.com/@eljuaniquilador | K13: @eljuaniquilador | L13: Not on Spotify | M13: No matching show or artist found; no Spotify link on YouTube page
A14: 11 | B14: Blog das irmãs | C14: Family | D14: Brazil | E14: Portuguese | F14: 2850000 | G14: 812495983 | H14: 2276 | I14: Dec 30, 2014 | J14: https://www.youtube.com/@blogdasirmãs | K14: @blogdasirmãs | L14: Not on Spotify | M14: No matching show or artist found; no Spotify link on YouTube page
A15: 12 | B15: Klarencio MC | C15: Gaming | D15: Mexico | E15: Spanish | F15: 2690000 | G15: 694389622 | H15: 166 | I15: Oct 8, 2023 | J15: https://www.youtube.com/@Klarencio | K15: @Klarencio | L15: Not on Spotify | M15: No matching show or artist found; no Spotify link on YouTube page
... A29: 26 | B29: Cocinando Corea | C29: Lifestyle | D29: Mexico | E29: Spanish | F29: 2009999 | G29: 276470364 | H29: 1262 | I29: Aug 24, 2017 | J29: https://www.youtube.com/@CocinandoCorea | K29: @CocinandoCorea | L29: Not on Spotify | M29: No matching show or artist found; no Spotify link on YouTube page

Sheet Summary
A1: Summary (Top 100, not on Spotify)
A3: Category | B3: Channels | C3: Replacements | D3: Total subscribers | F3: Country | G3: Channels
A4: Gaming | B4: =COUNTIF('Top 100 (not on Spotify)'!$C$4:$C$103,A4) | C4: =COUNTIFS('Top 100 (not on Spotify)'!$C$4:$C$103,A4,'Top 100 (not on Spotify)'!$N$4:$N$103,"Yes") | D4: =SUMIF('Top 100 (not on Spotify)'!$C$4:$C$103,A4,'Top 100 (not on Spotify)'!$F$4:$F$103) | F4: Argentina | G4: =COUNTIF('Top 100 (not on Spotify)'!$D$4:$D$103,F4)
A5: Comedy | B5: =COUNTIF('Top 100 (not on Spotify)'!$C$4:$C$103,A5) | C5: =COUNTIFS('Top 100 (not on Spotify)'!$C$4:$C$103,A5,'Top 100 (not on Spotify)'!$N$4:$N$103,"Yes") | D5: =SUMIF('Top 100 (not on Spotify)'!$C$4:$C$103,A5,'Top 100 (not on Spotify)'!$F$4:$F$103) | F5: Brazil | G5: =COUNTIF('Top 100 (not on Spotify)'!$D$4:$D$103,F5)
A6: Family | B6: =COUNTIF('Top 100 (not on Spotify)'!$C$4:$C$103,A6) | C6: =COUNTIFS('Top 100 (not on Spotify)'!$C$4:$C$103,A6,'Top 100 (not on Spotify)'!$N$4:$N$103,"Yes") | D6: =SUMIF('Top 100 (not on Spotify)'!$C$4:$C$103,A6,'Top 100 (not on Spotify)'!$F$4:$F$103) | F6: Colombia | G6: =COUNTIF('Top 100 (not on Spotify)'!$D$4:$D$103,F6)
A7: Lifestyle | B7: =COUNTIF('Top 100 (not on Spotify)'!$C$4:$C$103,A7) | C7: =COUNTIFS('Top 100 (not on Spotify)'!$C$4:$C$103,A7,'Top 100 (not on Spotify)'!$N$4:$N$103,"Yes") | D7: =SUMIF('Top 100 (not on Spotify)'!$C$4:$C$103,A7,'Top 100 (not on Spotify)'!$F$4:$F$103) | F7: Costa Rica | G7: =COUNTIF('Top 100 (not on Spotify)'!$D$4:$D$103,F7)
A8: Total | B8: =SUM(B4:B7) | C8: =SUM(C4:C7) | D8: =SUM(D4:D7) | F8: Ecuador | G8: =COUNTIF('Top 100 (not on Spotify)'!$D$4:$D$103,F8)
F9: Mexico | G9: =COUNTIF('Top 100 (not on Spotify)'!$D$4:$D$103,F9)
F10: Peru | G10: =COUNTIF('Top 100 (not on Spotify)'!$D$4:$D$103,F10)
F11: Total | G11: =SUM(G4:G10)
A14: How 'on Spotify' was decided
A15: • Each channel name was searched on Spotify (Podcasts & Shows, and Artists), and each channel's YouTube About page was scanned for Spotify links.
A16: • ON Spotify = the creator's own presence: a podcast/show published under their name, their own songs/artist profile, or a Spotify link on their YouTube page. Borderline cases were treated as ON Spotify and removed.
A17: • NOT on Spotify = nothing found, or only fan-uploaded shows / unrelated artists with the same name (e.g. an English rapper called 'T3ddy', a DJ called 'Lawler'). These are marked in the evidence column.
A18: • Replacements are the biggest LATAM channels (2M+ subs, country verified on YouTube) in the same category that passed the same Spotify check; replacements with only same-name matches were avoided where possible.
A19: • Spotify search is not exhaustive: a creator could still appear under a different name. Checked 27 Sep 2026.
A20: • Categories are editorial labels; many channels overlap (e.g. kids/family channels with gaming).
